<?xml version="1.0" encoding="UTF-8"?>
<sdf version='1.9'>
  <model name='hm3_drone'>
    <pose>0 0 .24 0 0 0</pose>
    <self_collide>false</self_collide>
    <static>false</static>

    <link name="base_link">
      <inertial>
        <mass>2.0</mass>
        <inertia>
          <ixx>0.15</ixx>
          <ixy>0</ixy>
          <ixz>0</ixz>
          <iyy>0.15</iyy>
          <iyz>0</iyz>
          <izz>0.25</izz>
        </inertia>
      </inertial>
      <gravity>true</gravity>
      <velocity_decay/>

      <visual name="base_link_visual">
        <pose>0 0 0 0 0 0</pose>
        <geometry>
          <box>
            <size>0.70 0.50 0.10</size>
          </box>
        </geometry>
        <material>
          <ambient>0.1 0.1 1.0 1.0</ambient>
          <diffuse>0.1 0.1 1.0 1.0</diffuse>
          <specular>0.5 0.5 0.5 1.0</specular>
        </material>
      </visual>

      <collision name="base_link_collision">
        <pose>0 0 0 0 0 0</pose>
        <geometry>
          <box>
            <size>0.70 0.50 0.10</size>
          </box>
        </geometry>
      </collision>

      <visual name="leg_1_visual">
        <pose>0.15 -0.15 -0.12 0 0 0</pose>
        <geometry>
          <cylinder><radius>0.015</radius><length>0.24</length></cylinder>
        </geometry>
        <material>
          <diffuse>0.35 0.6 0.35 1.0</diffuse>
        </material>
      </visual>
      <collision name="leg_1_collision">
        <pose>0.15 -0.15 -0.12 0 0 0</pose>
        <geometry>
          <cylinder><radius>0.015</radius><length>0.24</length></cylinder>
        </geometry>
      </collision>

      <visual name="leg_2_visual">
        <pose>-0.15 0.15 -0.12 0 0 0</pose>
        <geometry>
          <cylinder><radius>0.015</radius><length>0.24</length></cylinder>
        </geometry>
        <material>
          <diffuse>0.35 0.6 0.35 1.0</diffuse>
        </material>
      </visual>
      <collision name="leg_2_collision">
        <pose>-0.15 0.15 -0.12 0 0 0</pose>
        <geometry>
          <cylinder><radius>0.015</radius><length>0.24</length></cylinder>
        </geometry>
      </collision>

      <visual name="leg_3_visual">
        <pose>0.15 0.15 -0.12 0 0 0</pose>
        <geometry>
          <cylinder><radius>0.015</radius><length>0.24</length></cylinder>
        </geometry>
        <material>
          <diffuse>0.35 0.6 0.35 1.0</diffuse>
        </material>
      </visual>
      <collision name="leg_3_collision">
        <pose>0.15 0.15 -0.12 0 0 0</pose>
        <geometry>
          <cylinder><radius>0.015</radius><length>0.24</length></cylinder>
        </geometry>
      </collision>

      <visual name="leg_4_visual">
        <pose>-0.15 -0.15 -0.12 0 0 0</pose>
        <geometry>
          <cylinder><radius>0.015</radius><length>0.24</length></cylinder>
        </geometry>
        <material>
          <diffuse>0.35 0.6 0.35 1.0</diffuse>
        </material>
      </visual>
      <collision name="leg_4_collision">
        <pose>-0.15 -0.15 -0.12 0 0 0</pose>
        <geometry>
          <cylinder><radius>0.015</radius><length>0.24</length></cylinder>
        </geometry>
      </collision>

      <sensor name="air_pressure_sensor" type="air_pressure">
        <always_on>1</always_on><update_rate>50</update_rate>
        <air_pressure>
          <pressure>
            <noise type="gaussian">
              <mean>0</mean><stddev>3</stddev>
            </noise>
          </pressure>
        </air_pressure>
      </sensor>
      <sensor name="magnetometer_sensor" type="magnetometer">
        <always_on>1</always_on><update_rate>100</update_rate>
        <magnetometer>
          <x><noise type="gaussian"><stddev>0.0001</stddev></noise></x>
          <y><noise type="gaussian"><stddev>0.0001</stddev></noise></y>
          <z><noise type="gaussian"><stddev>0.0001</stddev></noise></z>
        </magnetometer>
      </sensor>
      <sensor name="imu_sensor" type="imu">
        <always_on>1</always_on><update_rate>250</update_rate>
        <imu>
          <angular_velocity>
            <x><noise type="gaussian"><mean>0.0</mean><stddev>0.00087</stddev></noise></x>
            <y><noise type="gaussian"><mean>0.0</mean><stddev>0.00087</stddev></noise></y>
            <z><noise type="gaussian"><mean>0.0</mean><stddev>0.00087</stddev></noise></z>
          </angular_velocity>
          <linear_acceleration>
            <x><noise type="gaussian"><mean>0.0</mean><stddev>0.00637</stddev></noise></x>
            <y><noise type="gaussian"><mean>0.0</mean><stddev>0.00637</stddev></noise></y>
            <z><noise type="gaussian"><mean>0.0</mean><stddev>0.00686</stddev></noise></z>
          </linear_acceleration>
        </imu>
      </sensor>
      <sensor name="navsat_sensor" type="navsat">
        <always_on>1</always_on><update_rate>30</update_rate>
      </sensor>
    </link>

    <link name="rotor_0">
      <pose>0.35 -0.25 0.06 0 0 0</pose>

      <inertial>
        <mass>0.016</mass>
        <inertia>
          <ixx>3.84e-07</ixx>
          <iyy>2.61e-05</iyy>
          <izz>2.64e-05</izz>
        </inertia>
      </inertial>
      <visual name="rotor_0_visual">
        <pose>-0.022 -0.146 -0.016 0 0 0</pose>
        <geometry>
          <mesh>
            <scale>0.85 0.85 0.85</scale>
            <uri>model://x500_base/meshes/1345_prop_ccw.stl</uri>
          </mesh>
        </geometry>
        <material><diffuse>1 1 1 1</diffuse></material>
      </visual>
      <collision name="rotor_0_collision">
        <geometry><cylinder><radius>0.16</radius><length>0.01</length></cylinder></geometry>
      </collision>
    </link>
    <joint name="rotor_0_joint" type="revolute">
      <parent>base_link</parent><child>rotor_0</child>
      <axis><xyz>0 0 1</xyz>
        <limit><lower>-1e16</lower><upper>1e16</upper></limit>
      </axis>
    </joint>

    <link name="rotor_1">
      <pose>-0.35 0.25 0.06 0 0 0</pose>

      <inertial>
        <mass>0.016</mass>
        <inertia>
          <ixx>3.84e-07</ixx>
          <iyy>2.61e-05</iyy>
          <izz>2.64e-05</izz>
        </inertia>
      </inertial>
      <visual name="rotor_1_visual">
        <pose>-0.022 -0.146 -0.016 0 0 0</pose>
        <geometry>
          <mesh>
            <scale>0.85 0.85 0.85</scale>
            <uri>model://x500_base/meshes/1345_prop_cw.stl</uri>
          </mesh>
        </geometry>
      </visual>
      <collision name="rotor_1_collision">
        <geometry><cylinder><radius>0.16</radius><length>0.01</length></cylinder></geometry>
      </collision>
    </link>
    <joint name="rotor_1_joint" type="revolute">
      <parent>base_link</parent><child>rotor_1</child>
      <axis><xyz>0 0 1</xyz>
        <limit><lower>-1e16</lower><upper>1e16</upper></limit>
      </axis>
    </joint>

    <link name="rotor_2">
      <pose>0.35 0.25 0.06 0 0 0</pose>

      <inertial>
        <mass>0.016</mass>
        <inertia>
          <ixx>3.84e-07</ixx>
          <iyy>2.61e-05</iyy>
          <izz>2.64e-05</izz>
        </inertia>
      </inertial>
      <visual name="rotor_2_visual">
        <pose>-0.022 -0.146 -0.016 0 0 0</pose>
        <geometry>
          <mesh>
            <scale>0.85 0.85 0.85</scale>
            <uri>model://x500_base/meshes/1345_prop_cw.stl</uri>
          </mesh>
        </geometry>
        <material><diffuse>1 1 1 1</diffuse></material>
      </visual>
      <collision name="rotor_2_collision">
        <geometry><cylinder><radius>0.16</radius><length>0.01</length></cylinder></geometry>
      </collision>
    </link>
    <joint name="rotor_2_joint" type="revolute">
      <parent>base_link</parent><child>rotor_2</child>
      <axis><xyz>0 0 1</xyz>
        <limit><lower>-1e16</lower><upper>1e16</upper></limit>
      </axis>
    </joint>

    <link name="rotor_3">
      <pose>-0.35 -0.25 0.06 0 0 0</pose>

      <inertial>
        <mass>0.016</mass>
        <inertia>
          <ixx>3.84e-07</ixx>
          <iyy>2.61e-05</iyy>
          <izz>2.64e-05</izz>
        </inertia>
      </inertial>
      <visual name="rotor_3_visual">
        <pose>-0.022 -0.146 -0.016 0 0 0</pose>
        <geometry>
          <mesh>
            <scale>0.85 0.85 0.85</scale>
            <uri>model://x500_base/meshes/1345_prop_ccw.stl</uri>
          </mesh>
        </geometry>
      </visual>
      <collision name="rotor_3_collision">
        <geometry><cylinder><radius>0.16</radius><length>0.01</length></cylinder></geometry>
      </collision>
    </link>
    <joint name="rotor_3_joint" type="revolute">
      <parent>base_link</parent><child>rotor_3</child>
      <axis><xyz>0 0 1</xyz>
        <limit><lower>-1e16</lower><upper>1e16</upper></limit>
      </axis>
    </joint>

    <link name="rotor_4">
      <pose>0 0.25 0.06 0 0 0</pose>

      <inertial>
        <mass>0.016</mass>
        <inertia>
          <ixx>3.84e-07</ixx>
          <iyy>2.61e-05</iyy>
          <izz>2.64e-05</izz>
        </inertia>
      </inertial>
      <visual name="rotor_4_visual">
        <pose>-0.022 -0.146 -0.016 0 0 0</pose>
        <geometry>
          <mesh>
            <scale>0.85 0.85 0.85</scale>
            <uri>model://x500_base/meshes/1345_prop_ccw.stl</uri>
          </mesh>
        </geometry>
      </visual>
      <collision name="rotor_4_collision">
        <geometry><cylinder><radius>0.16</radius><length>0.01</length></cylinder></geometry>
      </collision>
    </link>
    <joint name="rotor_4_joint" type="revolute">
      <parent>base_link</parent><child>rotor_4</child>
      <axis><xyz>0 0 1</xyz>
        <limit><lower>-1e16</lower><upper>1e16</upper></limit>
      </axis>
    </joint>

    <link name="rotor_5">
      <pose>0 -0.25 0.06 0 0 0</pose>

      <inertial>
        <mass>0.016</mass>
        <inertia>
          <ixx>3.84e-07</ixx>
          <iyy>2.61e-05</iyy>
          <izz>2.64e-05</izz>
        </inertia>
      </inertial>
      <visual name="rotor_5_visual">
        <pose>-0.022 -0.146 -0.016 0 0 0</pose>
        <geometry>
          <mesh>
            <scale>0.85 0.85 0.85</scale>
            <uri>model://x500_base/meshes/1345_prop_cw.stl</uri>
          </mesh>
        </geometry>
      </visual>
      <collision name="rotor_5_collision">
        <geometry><cylinder><radius>0.16</radius><length>0.01</length></cylinder></geometry>
      </collision>
    </link>
    <joint name="rotor_5_joint" type="revolute">
      <parent>base_link</parent><child>rotor_5</child>
      <axis><xyz>0 0 1</xyz>
        <limit><lower>-1e16</lower><upper>1e16</upper></limit>
      </axis>
    </joint>

    <plugin filename="gz-sim-multicopter-motor-model-system" name="gz::sim::systems::MulticopterMotorModel">
      <jointName>rotor_0_joint</jointName><linkName>rotor_0</linkName><turningDirection>ccw</turningDirection>
      <timeConstantUp>0.0125</timeConstantUp><timeConstantDown>0.025</timeConstantDown><maxRotVelocity>1000.0</maxRotVelocity><motorConstant>8.54858e-06</motorConstant><momentConstant>0.016</momentConstant><commandSubTopic>command/motor_speed</commandSubTopic><motorNumber>0</motorNumber><rotorDragCoefficient>8.06428e-05</rotorDragCoefficient><rollingMomentCoefficient>1e-06</rollingMomentCoefficient><rotorVelocitySlowdownSim>10</rotorVelocitySlowdownSim><motorType>velocity</motorType>
    </plugin>
    <plugin filename="gz-sim-multicopter-motor-model-system" name="gz::sim::systems::MulticopterMotorModel">
      <jointName>rotor_1_joint</jointName><linkName>rotor_1</linkName><turningDirection>cw</turningDirection>
      <timeConstantUp>0.0125</timeConstantUp><timeConstantDown>0.025</timeConstantDown><maxRotVelocity>1000.0</maxRotVelocity><motorConstant>8.54858e-06</motorConstant><momentConstant>0.016</momentConstant><commandSubTopic>command/motor_speed</commandSubTopic><motorNumber>1</motorNumber><rotorDragCoefficient>8.06428e-05</rotorDragCoefficient><rollingMomentCoefficient>1e-06</rollingMomentCoefficient><rotorVelocitySlowdownSim>10</rotorVelocitySlowdownSim><motorType>velocity</motorType>
    </plugin>
    <plugin filename="gz-sim-multicopter-motor-model-system" name="gz::sim::systems::MulticopterMotorModel">
      <jointName>rotor_2_joint</jointName><linkName>rotor_2</linkName><turningDirection>cw</turningDirection>
      <timeConstantUp>0.0125</timeConstantUp><timeConstantDown>0.025</timeConstantDown><maxRotVelocity>1000.0</maxRotVelocity><motorConstant>8.54858e-06</motorConstant><momentConstant>0.016</momentConstant><commandSubTopic>command/motor_speed</commandSubTopic><motorNumber>2</motorNumber><rotorDragCoefficient>8.06428e-05</rotorDragCoefficient><rollingMomentCoefficient>1e-06</rollingMomentCoefficient><rotorVelocitySlowdownSim>10</rotorVelocitySlowdownSim><motorType>velocity</motorType>
    </plugin>
    <plugin filename="gz-sim-multicopter-motor-model-system" name="gz::sim::systems::MulticopterMotorModel">
      <jointName>rotor_3_joint</jointName><linkName>rotor_3</linkName><turningDirection>ccw</turningDirection>
      <timeConstantUp>0.0125</timeConstantUp><timeConstantDown>0.025</timeConstantDown><maxRotVelocity>1000.0</maxRotVelocity><motorConstant>8.54858e-06</motorConstant><momentConstant>0.016</momentConstant><commandSubTopic>command/motor_speed</commandSubTopic><motorNumber>3</motorNumber><rotorDragCoefficient>8.06428e-05</rotorDragCoefficient><rollingMomentCoefficient>1e-06</rollingMomentCoefficient><rotorVelocitySlowdownSim>10</rotorVelocitySlowdownSim><motorType>velocity</motorType>
    </plugin>
    <plugin filename="gz-sim-multicopter-motor-model-system" name="gz::sim::systems::MulticopterMotorModel">
      <jointName>rotor_4_joint</jointName><linkName>rotor_4</linkName><turningDirection>ccw</turningDirection>
      <timeConstantUp>0.0125</timeConstantUp><timeConstantDown>0.025</timeConstantDown><maxRotVelocity>1000.0</maxRotVelocity><motorConstant>8.54858e-06</motorConstant><momentConstant>0.016</momentConstant><commandSubTopic>command/motor_speed</commandSubTopic><motorNumber>4</motorNumber><rotorDragCoefficient>8.06428e-05</rotorDragCoefficient><rollingMomentCoefficient>1e-06</rollingMomentCoefficient><rotorVelocitySlowdownSim>10</rotorVelocitySlowdownSim><motorType>velocity</motorType>
    </plugin>
    <plugin filename="gz-sim-multicopter-motor-model-system" name="gz::sim::systems::MulticopterMotorModel">
      <jointName>rotor_5_joint</jointName><linkName>rotor_5</linkName><turningDirection>cw</turningDirection>
      <timeConstantUp>0.0125</timeConstantUp><timeConstantDown>0.025</timeConstantDown><maxRotVelocity>1000.0</maxRotVelocity><motorConstant>8.54858e-06</motorConstant><momentConstant>0.016</momentConstant><commandSubTopic>command/motor_speed</commandSubTopic><motorNumber>5</motorNumber><rotorDragCoefficient>8.06428e-05</rotorDragCoefficient><rollingMomentCoefficient>1e-06</rollingMomentCoefficient><rotorVelocitySlowdownSim>10</rotorVelocitySlowdownSim><motorType>velocity</motorType>
    </plugin>
  </model>
</sdf>

